<mujoco model="jaka_manip">
  <compiler angle="radian" autolimits="true"/>

  <default>
    <default class="jaka">
      <joint axis="0 1 0" range="-6.28319 6.28319" armature="0.1"/>
      <position ctrlrange="-6.2831 6.2831"/>
      <general biastype="affine" ctrlrange="-6.2831 6.2831" gainprm="5000" biasprm="0 -5000 -500"/>
    </default>
    <default class="2f85">
      <mesh scale="0.001 0.001 0.001"/>
      <general biastype="affine"/>
      <site type="sphere" rgba="0.9 0.9 0.9 1" size="0.005" group="4"/>
      <joint axis="1 0 0"/>
      <default class="driver">
        <joint range="0 0.8" armature="0.005" damping="0.1" solimplimit="0.95 0.99 0.001" solreflimit="0.005 1"/>
      </default>
      <default class="follower">
        <joint range="-0.872664 0.872664" pos="0 -0.018 0.0065" solimplimit="0.95 0.99 0.001" solreflimit="0.005 1"/>
      </default>
      <default class="spring_link">
        <joint range="-0.29670597283 0.8" stiffness="0.05" springref="2.62" damping="0.00125"/>
      </default>
      <default class="coupler">
        <joint range="-1.57 0" solimplimit="0.95 0.99 0.001" solreflimit="0.005 1"/>
      </default>
      <default class="2f85/visual">
        <geom type="mesh" contype="0" conaffinity="0" group="2"/>
      </default>
      <default class="2f85/collision">
        <geom type="mesh" group="3"/>
        <default class="pad_box1">
          <geom mass="0" type="box" pos="0 -0.0026 0.028125" size="0.011 0.004 0.009375" friction="0.7"
            solimp="0.95 0.99 0.001" solref="0.004 1" priority="1" rgba="0.55 0.55 0.55 1"/>
        </default>
        <default class="pad_box2">
          <geom mass="0" type="box" pos="0 -0.0026 0.009375" size="0.011 0.004 0.009375" friction="0.6"
            solimp="0.95 0.99 0.001" solref="0.004 1" priority="1" rgba="0.45 0.45 0.45 1"/>
        </default>
      </default>
    </default>
  </default>

  <asset>
    <material name="gray" rgba="0.4627 0.4627 0.4627 1"/>
    <material name="black" rgba="0.149 0.149 0.149 1"/>

    <mesh name="link0" file="./assets/base_link.STL"/>
    <mesh name="link1" file="./assets/1.STL"/>
    <mesh name="link2" file="./assets/2.STL"/>
    <mesh name="link3" file="./assets/3.STL"/>
    <mesh name="link4" file="./assets/4.STL"/>
    <mesh name="link5" file="./assets/5.STL"/>
    <mesh name="link6" file="./assets/6.STL"/>

    <mesh name="mount_Link" file="../kinect_dk/assets/mount_v2.STL"/>
    <mesh name="camera_Link" file="../kinect_dk/assets/Azure Kinect DK.STL"/>

    <mesh class="2f85" file="../robotiq_2f85/assets/base_mount.stl"/>
    <mesh class="2f85" file="../robotiq_2f85/assets/base.stl"/>
    <mesh class="2f85" file="../robotiq_2f85/assets/driver.stl"/>
    <mesh class="2f85" file="../robotiq_2f85/assets/coupler.stl"/>
    <mesh class="2f85" file="../robotiq_2f85/assets/follower.stl"/>
    <mesh class="2f85" file="../robotiq_2f85/assets/pad.stl"/>
    <mesh class="2f85" file="../robotiq_2f85/assets/silicone_pad.stl"/>
    <mesh class="2f85" file="../robotiq_2f85/assets/spring_link.stl"/>
  </asset>

  <worldbody>
    <body name="link0" pos="0 0 0.05" childclass="jaka">
      <geom type="mesh" contype="0" conaffinity="0" group="1" rgba="1 1 1 1" mesh="link0" />
      <geom type="mesh" rgba="1 1 1 1" mesh="link0"/>
      <body name="Link_1" pos="0 0 0.10765">
        <inertial pos="-0.000328432 0.0040609 -0.0250109" quat="0.494863 -0.0216305 0.0243938 0.868359" mass="3.78" diaginertia="0.0405059 0.0403714 0.0342898"/>
        <joint name="joint1" pos="0 0 0" axis="0 0 1" limited="true" range="-6.28 6.28"/>
        <geom type="mesh" rgba="1 1 1 1" mesh="link1"/>
        <body name="Link_2" quat="0.707105 0.707108 0 0">
          <inertial pos="0.2975 -1.25165e-08 -0.16607" quat="0.499974 0.499521 0.500477 0.500027" mass="12.44" diaginertia="1.66881 1.65303 0.116455"/>
          <joint name="joint2" pos="0 0 0" axis="0 0 1" limited="true" range="-1.48 4.62"/>
          <geom type="mesh" rgba="1 1 1 1" mesh="link2"/>
          <body name="Link_3" pos="0.595 0 0">
            <inertial pos="0.294234 -4.72319e-06 -0.0241861" quat="-0.00022526 0.704551 -0.000206596 0.709653" mass="5.06" diaginertia="0.498538 0.497634 0.021265"/>
            <joint name="joint3" pos="0 0 0" axis="0 0 1" limited="true" range="-3.05 3.05"/>
            <geom type="mesh" rgba="1 1 1 1" mesh="link3"/>
            <body name="Link_4" pos="0.5715 0 -0.1315">
              <inertial pos="4.22018e-06 -0.0150344 0.00216594" quat="0.677782 0.701328 0.159558 -0.152616" mass="0.883" diaginertia="0.00459197 0.0045525 0.00363768"/>
              <joint name="joint4" pos="0 0 0" axis="0 0 1" limited="true" range="-1.48 4.62"/>
              <geom type="mesh" rgba="1 1 1 1" mesh="link4"/>
              <body name="Link_5" pos="0 -0.115 0" quat="0.707105 0.707108 0 0">
                <inertial pos="3.86595e-06 0.0042653 -0.00184283" quat="0.695151 0.688192 -0.146515 0.147274" mass="1" diaginertia="0.0070303 0.00698932 0.00413442"/>
                <joint name="joint5" pos="0 0 0" axis="0 0 1" limited="true" range="-6.28 6.28"/>
                <geom type="mesh" rgba="1 1 1 1" mesh="link5"/>
                <body name="Link_6" pos="0 0.1035 0" quat="0.707105 -0.707108 0 0">
                  <inertial pos="-0.000786085 3.88801e-05 -0.0163247" quat="-0.134296 0.689453 0.135461 0.698763" mass="0.22" diaginertia="0.00106472 0.000657738 0.000588131"/>
                  <joint name="joint6" pos="0 0 0" axis="0 0 1" limited="true" range="-6.28 6.28"/>
                  <geom type="mesh" rgba="1 1 1 1" mesh="link6"/>
                  <geom pos="0 0 0" quat="0 1 0 0" type="mesh" rgba="0.792157 0.819608 0.933333 1" mesh="mount_Link"/>
                  <geom pos="0 -0.0735 -0.021" quat="1 0 0 0" type="mesh" rgba="0.941176 0.941176 0.941176 1" mesh="camera_Link"/>
                  <camera name="handcam_depth" pos="0 -0.073 -0.01" fovy="70" quat="0 1 -1 0"/>
                  <camera name="handcam_rgb" pos="-0.032 -0.071 -0.01" fovy="75" quat="0 1 -1 0"/>
                  <body name="attachment" pos="0 0 0.01" quat="0.707107 0 0 -0.707107">
                    <site name="attachment_site" quat="0 0 0 1"/>
                    <body name="base_mount" quat="-1 0 0 1" childclass="2f85">
                      <geom class="2f85/visual" mesh="base_mount" material="black"/>
                      <geom class="2f85/collision" mesh="base_mount"/>
                      <body name="base" pos="0 0 0.0038" quat="1 0 0 -1">
                        <inertial mass="0.777441" pos="0 -2.70394e-05 0.0354675" quat="1 -0.00152849 0 0"
                          diaginertia="0.000260285 0.000225381 0.000152708"/>
                        <geom class="2f85/visual" mesh="base" material="black"/>
                        <geom class="2f85/collision" mesh="base"/>
                        <site name="pinch" pos="0 0 0.145"/>
                        <body name="right_driver" pos="0 0.0306011 0.054904">
                          <inertial mass="0.00899563" pos="2.96931e-12 0.0177547 0.00107314"
                            quat="0.681301 0.732003 0 0" diaginertia="1.72352e-06 1.60906e-06 3.22006e-07"/>
                          <joint name="right_driver_joint" class="driver"/>
                          <geom class="2f85/visual" mesh="driver" material="gray"/>
                          <geom class="2f85/collision" mesh="driver"/>
                          <body name="right_coupler" pos="0 0.0315 -0.0041">
                            <inertial mass="0.0140974" pos="0 0.00301209 0.0232175"
                              quat="0.705636 -0.0455904 0.0455904 0.705636"
                              diaginertia="4.16206e-06 3.52216e-06 8.88131e-07"/>
                            <joint name="right_coupler_joint" class="coupler"/>
                            <geom class="2f85/visual" mesh="coupler" material="black"/>
                            <geom class="2f85/collision" mesh="coupler"/>
                          </body>
                        </body>
                        <body name="right_spring_link" pos="0 0.0132 0.0609">
                          <inertial mass="0.0221642" pos="-8.65005e-09 0.0181624 0.0212658"
                            quat="0.663403 -0.244737 0.244737 0.663403"
                            diaginertia="8.96853e-06 6.71733e-06 2.63931e-06"/>
                          <joint name="right_spring_link_joint" class="spring_link"/>
                          <geom class="2f85/visual" mesh="spring_link" material="black"/>
                          <geom class="2f85/collision" mesh="spring_link"/>
                          <body name="right_follower" pos="0 0.055 0.0375">
                            <inertial mass="0.0125222" pos="0 -0.011046 0.0124786" quat="1 0.1664 0 0"
                              diaginertia="2.67415e-06 2.4559e-06 6.02031e-07"/>
                            <joint name="right_follower_joint" class="follower"/>
                            <geom class="2f85/visual" mesh="follower" material="black"/>
                            <geom class="2f85/collision" mesh="follower"/>
                            <body name="right_pad" pos="0 -0.0189 0.01352">
                              <geom class="pad_box1" name="right_pad1"/>
                              <geom class="pad_box2" name="right_pad2"/>
                              <inertial mass="0.0035" pos="0 -0.0025 0.0185" quat="0.707107 0 0 0.707107"
                                diaginertia="4.73958e-07 3.64583e-07 1.23958e-07"/>
                              <geom class="2f85/visual" mesh="pad"/>
                              <body name="right_silicone_pad">
                                <geom class="2f85/visual" mesh="silicone_pad" material="black"/>
                              </body>
                            </body>
                          </body>
                        </body>
                        <body name="left_driver" pos="0 -0.0306011 0.054904" quat="0 0 0 1">
                          <inertial mass="0.00899563" pos="0 0.0177547 0.00107314" quat="0.681301 0.732003 0 0"
                            diaginertia="1.72352e-06 1.60906e-06 3.22006e-07"/>
                          <joint name="left_driver_joint" class="driver"/>
                          <geom class="2f85/visual" mesh="driver" material="gray"/>
                          <geom class="2f85/collision" mesh="driver"/>
                          <body name="left_coupler" pos="0 0.0315 -0.0041">
                            <inertial mass="0.0140974" pos="0 0.00301209 0.0232175"
                              quat="0.705636 -0.0455904 0.0455904 0.705636"
                              diaginertia="4.16206e-06 3.52216e-06 8.88131e-07"/>
                            <joint name="left_coupler_joint" class="coupler"/>
                            <geom class="2f85/visual" mesh="coupler" material="black"/>
                            <geom class="2f85/collision" mesh="coupler"/>
                          </body>
                        </body>
                        <body name="left_spring_link" pos="0 -0.0132 0.0609" quat="0 0 0 1">
                          <inertial mass="0.0221642" pos="-8.65005e-09 0.0181624 0.0212658"
                            quat="0.663403 -0.244737 0.244737 0.663403"
                            diaginertia="8.96853e-06 6.71733e-06 2.63931e-06"/>
                          <joint name="left_spring_link_joint" class="spring_link"/>
                          <geom class="2f85/visual" mesh="spring_link" material="black"/>
                          <geom class="2f85/collision" mesh="spring_link"/>
                          <body name="left_follower" pos="0 0.055 0.0375">
                            <inertial mass="0.0125222" pos="0 -0.011046 0.0124786" quat="1 0.1664 0 0"
                              diaginertia="2.67415e-06 2.4559e-06 6.02031e-07"/>
                            <joint name="left_follower_joint" class="follower"/>
                            <geom class="2f85/visual" mesh="follower" material="black"/>
                            <geom class="2f85/collision" mesh="follower"/>
                            <body name="left_pad" pos="0 -0.0189 0.01352">
                              <geom class="pad_box1" name="left_pad1"/>
                              <geom class="pad_box2" name="left_pad2"/>
                              <inertial mass="0.0035" pos="0 -0.0025 0.0185" quat="1 0 0 1"
                                diaginertia="4.73958e-07 3.64583e-07 1.23958e-07"/>
                              <geom class="2f85/visual" mesh="pad"/>
                              <body name="left_silicone_pad">
                                <geom class="2f85/visual" mesh="silicone_pad" material="black"/>
                              </body>
                            </body>
                          </body>
                        </body>
                      </body>
                    </body>
                  </body>
                </body>
              </body>
            </body>
          </body>
        </body>
      </body>
    </body>
  </worldbody>

  <contact>
    <exclude body1="base" body2="left_driver"/>
    <exclude body1="base" body2="right_driver"/>
    <exclude body1="base" body2="left_spring_link"/>
    <exclude body1="base" body2="right_spring_link"/>
    <exclude body1="right_coupler" body2="right_follower"/>
    <exclude body1="left_coupler" body2="left_follower"/>
  </contact>

  <tendon>
    <fixed name="split">
      <joint joint="right_driver_joint" coef="0.5"/>
      <joint joint="left_driver_joint" coef="0.5"/>
    </fixed>
  </tendon>

  <equality>
    <connect anchor="0 0 0" body1="right_follower" body2="right_coupler" solimp="0.95 0.99 0.001" solref="0.005 1"/>
    <connect anchor="0 0 0" body1="left_follower" body2="left_coupler" solimp="0.95 0.99 0.001" solref="0.005 1"/>
    <joint joint1="right_driver_joint" joint2="left_driver_joint" polycoef="0 1 0 0 0" solimp="0.95 0.99 0.001"
      solref="0.005 1"/>
  </equality>

  <actuator>
    <general class="jaka" name="actuator1" joint="joint1" gainprm="4500" biasprm="0 -4500 -450" forcerange="-330 330" ctrlrange="-6.28 6.28"/>
    <general class="jaka" name="actuator2" joint="joint2" gainprm="4500" biasprm="0 -4500 -450" forcerange="-330 330" ctrlrange="-1.48 4.62"/>
    <general class="jaka" name="actuator3" joint="joint3" gainprm="3500" biasprm="0 -3500 -350" forcerange="-150 150" ctrlrange="-3.05 3.05"/>
    <general class="jaka" name="actuator4" joint="joint4" gainprm="2000" biasprm="0 -2000 -200" forcerange="-56 56" ctrlrange="-1.48 4.62"/>
    <general class="jaka" name="actuator5" joint="joint5" gainprm="2000" biasprm="0 -2000 -200" forcerange="-56 56" ctrlrange="-6.28 6.28"/>
    <general class="jaka" name="actuator6" joint="joint6" gainprm="2000" biasprm="0 -2000 -200" forcerange="-56 56" ctrlrange="-6.28 6.28"/>
    <general class="2f85" name="fingers_actuator" tendon="split" forcerange="-5 5" ctrlrange="0 255"
      gainprm="0.3137255 0 0" biasprm="0 -100 -10"/>
  </actuator>

</mujoco>
