<mujoco model="ur10_manip">
  <compiler angle="radian" autolimits="true"/>

  <default>
    <default class="ur10">
      <joint axis="0 1 0" range="-6.28319 6.28319" armature="0.1"/>
      <position ctrlrange="-6.2831 6.2831"/>
      <general biastype="affine" ctrlrange="-6.2831 6.2831" gainprm="5000" biasprm="0 -5000 -500"/>
    </default>
  </default>

  <asset>
    <mesh name="base0" file="./assets/base.stl"/>
    <mesh name="shoulder" file="./assets/shoulder.stl"/>
    <mesh name="upperarm" file="./assets/upperarm.stl"/>
    <mesh name="forearm" file="./assets/forearm.stl"/>
    <mesh name="wrist1" file="./assets/wrist1.stl"/>
    <mesh name="wrist2" file="./assets/wrist2.stl"/>
    <mesh name="wrist3" file="./assets/wrist3.stl"/>

    <mesh name="mount_Link" file="../kinect_dk/assets/mount_v2.STL"/>
    <mesh name="camera_Link" file="../kinect_dk/assets/Azure Kinect DK.STL"/>

    <mesh name="tool_p1" file="../parts/peg_in_hole/assets/peg_p1.STL"/>
    <mesh name="tool_p2" file="../parts/peg_in_hole/assets/peg_p2_290.STL"/>
    <mesh name="hole_part" file="../parts/peg_in_hole/assets/hole_part_36.STL"/>
  </asset>

  <worldbody>
    <body name="base0" childclass="ur10">
      <geom quat="-1 0 0 0" type="mesh" rgba="0.7 0.7 0.7 1" mesh="base0"/>
      <body name="shoulder_link" pos="0 0 0.1273" quat="0 0 0 1">
        <inertial pos="0.021 -0.027 0" quat="0.988634 -0.000680926 0.148578 -0.0229591" mass="7.1" diaginertia="0.0353866 0.0352903 0.0202532"/>
        <joint name="joint1" pos="0 0 0" axis="0 0 1" range="-6.28319 6.28319" damping="10"/>
        <geom quat="0 0 0 1" type="mesh" rgba="0.7 0.7 0.7 1" mesh="shoulder"/>
        <body name="upper_arm_link" quat="0.707107 0.707107 0 0">
          <inertial pos="-0.232 0 0.158" quat="0.500033 0.499784 0.489585 0.510381" mass="12.7" diaginertia="0.77068 0.769758 0.0278114"/>
          <joint name="joint2" pos="0 0 0" axis="0 0 1" range="-6.28319 6.28319" damping="10"/>
          <geom pos="0 0 0.220941" quat="0.5 0.5 -0.5 -0.5" type="mesh" rgba="0.7 0.7 0.7 1" mesh="upperarm"/>
          <body name="forearm_link" pos="-0.612 0 0">
            <inertial pos="-0.3323 0 0.068" quat="0.492051 0.507971 0.507346 0.492394" mass="4.27" diaginertia="0.30928 0.306743 0.00985709"/>
            <joint name="joint3" pos="0 0 0" axis="0 0 1" range="-3.14159 3.14159" damping="5"/>
            <geom pos="0 0 0.049042" quat="0.5 0.5 -0.5 -0.5" type="mesh" rgba="0.7 0.7 0.7 1" mesh="forearm"/>
            <body name="wrist_1_link" pos="-0.5723 0 0.163941">
              <inertial pos="0 -0.018 0.007" quat="0.525776 0.850564 -0.0100431 9.45801e-05" mass="2" diaginertia="0.00296017 0.00269992 0.00209991"/>
              <joint name="joint4" pos="0 0 0" axis="0 0 1" range="-6.28319 6.28319" damping="2"/>
              <geom pos="0 0 -0.1149" quat="0.707107 0.707107 0 0" type="mesh" rgba="0.7 0.7 0.7 1" mesh="wrist1"/>
              <body name="wrist_2_link" pos="0 -0.1157 -2.37305e-11" quat="0.707107 0.707107 0 0">
                <inertial pos="0 0.018 -0.007" quat="0.525776 0.850564 -0.0100431 9.45801e-05" mass="2" diaginertia="0.00296017 0.00269992 0.00209991"/>
                <joint name="joint5" pos="0 0 0" axis="0 0 1" range="-6.28319 6.28319" damping="2"/>
                <geom pos="0 0 -0.1158" quat="1 0 0 0" type="mesh" rgba="0.7 0.7 0.7 1" mesh="wrist2"/>
                <body name="wrist_3_link" pos="0 0.0922 -1.89105e-11" quat="0.707107 -0.707107 0 0">
                  <inertial pos="0 0 -0.026" quat="0.707107 0 0 0.707107" mass="0.365" diaginertia="0.00041 0.0004 0.00034"/>
                  <joint name="joint6" pos="0 0 0" axis="0 0 1" range="-6.28319 6.28319" damping="2"/>
                  <geom pos="0 0 -0.0922" quat="0.707107 0.707107 0 0" type="mesh" rgba="0.7 0.7 0.7 1" mesh="wrist3"/>
                  <geom pos="0 0 0" quat="0 1 0 0" type="mesh" rgba="0.792157 0.819608 0.933333 1" mesh="mount_Link"/>
                  <geom pos="0 -0.0735 -0.021" quat="1 0 0 0" type="mesh" rgba="0.941176 0.941176 0.941176 1" mesh="camera_Link"/>
                  <camera name="handcam_depth" pos="0 -0.073 -0.01" fovy="70" quat="0 1 -1 0"/>
                  <camera name="handcam_rgb" pos="-0.032 -0.071 -0.01" fovy="75" quat="0 1 -1 0"/>
                  <body name="fts_sensor" pos="0 0 0.04" euler="3.1415926 0 1.570796327">
                    <geom type="cylinder" size="0.04 0.033605" rgba="0.7 0.7 .7 0.5" />
                    <inertial pos="0 0 0" mass="0.000000001" diaginertia="0.000000001 0.000000001 0.000000001" />
                    <site name="fts_sensor_site" pos="0 0 -0.033605"/>
                    <body name="peg" pos="0 0 -0.033605" euler="0 0 0">
                        <geom type="mesh" pos="0 0 -0.01" rgba="1 1 1 1" mesh="tool_p1" />
                        <geom type="mesh" pos="0 0 -0.01" rgba="1 1 1 1" mesh="tool_p2" />
                    </body>
                  </body>
                </body>
              </body>
            </body>
          </body>
        </body>
      </body>
    </body>

    <body name="hole" pos="0 0.6 0.15">
      <geom type="mesh" rgba="1 1 1 -0.3" mesh="hole_part" />
      <geom type="mesh" euler="0 0 0.17453292519943295769" rgba="1 1 1 1" mesh="hole_part" />
      <geom type="mesh" euler="0 0 0.34906585039886591538" rgba="1 1 1 1" mesh="hole_part" />
      <geom type="mesh" euler="0 0 0.52359877559829887" rgba="1 1 1 1" mesh="hole_part" />
      <geom type="mesh" euler="0 0 0.698131700797731830769" rgba="1 1 1 1" mesh="hole_part" />
      <geom type="mesh" euler="0 0 0.8726646259971647884618" rgba="1 1 1 1" mesh="hole_part" />

      <body name="hole1" euler="0 0 1.04719755119659774615">
        <geom type="mesh" rgba="1 1 1 1" mesh="hole_part" />
        <geom type="mesh" euler="0 0 0.17453292519943295769" rgba="1 1 1 1" mesh="hole_part" />
        <geom type="mesh" euler="0 0 0.34906585039886591538" rgba="1 1 1 1" mesh="hole_part" />
        <geom type="mesh" euler="0 0 0.52359877559829887" rgba="1 1 1 1" mesh="hole_part" />
        <geom type="mesh" euler="0 0 0.698131700797731830769" rgba="1 1 1 1" mesh="hole_part" />
        <geom type="mesh" euler="0 0 0.8726646259971647884618" rgba="1 1 1 1" mesh="hole_part" />
        <body name="hole2" euler="0 0 1.04719755119659774615">
        <geom type="mesh" rgba="1 1 1 1" mesh="hole_part" />
        <geom type="mesh" euler="0 0 0.17453292519943295769" rgba="1 1 1 1" mesh="hole_part" />
        <geom type="mesh" euler="0 0 0.34906585039886591538" rgba="1 1 1 1" mesh="hole_part" />
        <geom type="mesh" euler="0 0 0.52359877559829887" rgba="1 1 1 1" mesh="hole_part" />
        <geom type="mesh" euler="0 0 0.698131700797731830769" rgba="1 1 1 1" mesh="hole_part" />
        <geom type="mesh" euler="0 0 0.8726646259971647884618" rgba="1 1 1 1" mesh="hole_part" />
        <body name="hole3" euler="0 0 1.04719755119659774615">
          <geom type="mesh" rgba="1 1 1 1" mesh="hole_part" />
          <geom type="mesh" euler="0 0 0.17453292519943295769" rgba="1 1 1 1" mesh="hole_part" />
          <geom type="mesh" euler="0 0 0.34906585039886591538" rgba="1 1 1 1" mesh="hole_part" />
          <geom type="mesh" euler="0 0 0.52359877559829887" rgba="1 1 1 1" mesh="hole_part" />
          <geom type="mesh" euler="0 0 0.698131700797731830769" rgba="1 1 1 1" mesh="hole_part" />
          <geom type="mesh" euler="0 0 0.8726646259971647884618" rgba="1 1 1 1" mesh="hole_part" />
            <body name="hole4" euler="0 0 1.04719755119659774615">
            <geom type="mesh" rgba="1 1 1 1" mesh="hole_part" />
            <geom type="mesh" euler="0 0 0.17453292519943295769" rgba="1 1 1 1" mesh="hole_part" />
            <geom type="mesh" euler="0 0 0.34906585039886591538" rgba="1 1 1 1" mesh="hole_part" />
            <geom type="mesh" euler="0 0 0.52359877559829887" rgba="1 1 1 1" mesh="hole_part" />
            <geom type="mesh" euler="0 0 0.698131700797731830769" rgba="1 1 1 1" mesh="hole_part" />
            <geom type="mesh" euler="0 0 0.8726646259971647884618" rgba="1 1 1 1" mesh="hole_part" />
              <body name="hole5" euler="0 0 1.04719755119659774615">
              <geom type="mesh" rgba="1 1 1 1" mesh="hole_part" />
              <geom type="mesh" euler="0 0 0.17453292519943295769" rgba="1 1 1 1" mesh="hole_part" />
              <geom type="mesh" euler="0 0 0.34906585039886591538" rgba="1 1 1 1" mesh="hole_part" />
              <geom type="mesh" euler="0 0 0.52359877559829887" rgba="1 1 1 1" mesh="hole_part" />
              <geom type="mesh" euler="0 0 0.698131700797731830769" rgba="1 1 1 1" mesh="hole_part" />
              <geom type="mesh" euler="0 0 0.8726646259971647884618" rgba="1 1 1 0.3" mesh="hole_part" />
              </body>
            </body>
          </body>
        </body>
      </body>
    </body>
  </worldbody>


  <sensor>
        <!-- The sensor data are stored in mujoco.MjData(model).sensordata, and the length is 3*1 force plus 3*1 torque -->
        <force name="fts_sensor_force" site="fts_sensor_site"/>
        <torque name="fts_sensor_torque" site="fts_sensor_site"/>
    </sensor>

  <actuator>
    <general class="ur10" name="actuator1" joint="joint1" gainprm="4500" biasprm="0 -4500 -450" forcerange="-330 330"/>
    <general class="ur10" name="actuator2" joint="joint2" gainprm="4500" biasprm="0 -4500 -450" forcerange="-330 330"/>
    <general class="ur10" name="actuator3" joint="joint3" gainprm="3500" biasprm="0 -3500 -350" forcerange="-150 150" ctrlrange="-3.1415 3.1415"/>
    <general class="ur10" name="actuator4" joint="joint4" gainprm="3500" biasprm="0 -3500 -350" forcerange="-56 56"/>
    <general class="ur10" name="actuator5" joint="joint5" gainprm="2000" biasprm="0 -2000 -200" forcerange="-56 56"/>
    <general class="ur10" name="actuator6" joint="joint6" gainprm="2000" biasprm="0 -2000 -200" forcerange="-56 56"/>
  </actuator>

  <keyframe>
    <key name="home" qpos="0 -1.5708 0 -1.5708 0 0"/>
  </keyframe>

</mujoco>
